Workbook

Sheet 1월
B1: ■ 우리카드 구간포상 이벤트_202601
G2: 2 | H2: 4 | I2: 6 | J2: 8 | K2: 10 | L2: 15 | M2: 20
B3: 구분 | C3: 이름 | D3: 휴대폰번호 | E3: 행번 | F3: 실적 | G3: 구간달성 | P3: 2 | Q3: 50000 | R3: =Q3 -> 50000
G4: 2좌 | H4: 4좌 | I4: 6좌 | J4: 8좌 | K4: 10좌 | L4: 15좌 | M4: 20좌 | N4: 누적 | P4: 4 | Q4: 100000 | R4: =Q3+Q4 -> 150000
B5: 합계 | D5: =COUNTA(C6:C194) -> 189 | N5: =SUM(N6:N194) -> 10650000 | P5: 6 | Q5: 200000 | R5: =Q3+Q4+Q5 -> 350000
B6: 1 | C6: 서동환 | D6: 01079271992 | E6: 31902942 | F6: 6 | G6: =IF(IFERROR(VLOOKUP($F6,$P:$P,1,1),0)>=G$2,"o","-") -> o | H6: =IF(IFERROR(VLOOKUP($F6,$P:$P,1,1),0)>=H$2,"o","-") -> o | I6: =IF(IFERROR(VLOOKUP($F6,$P:$P,1,1),0)>=I$2,"o","-") -> o | J6: =IF(IFERROR(VLOOKUP($F6,$P:$P,1,1),0)>=J$2,"o","-") -> - | K6: =IF(IFERROR(VLOOKUP($F6,$P:$P,1,1),0)>=K$2,"o","-") -> - | L6: =IF(IFERROR(VLOOKUP($F6,$P:$P,1,1),0)>=L$2,"o","-") -> - | M6: =IF(IFERROR(VLOOKUP($F6,$P:$P,1,1),0)>=M$2,"o","-") -> - | N6: =IFERROR(VLOOKUP(F6,$P:$R,3,1),0) -> 350000 | P6: 8 | Q6: 400000 | R6: =Q3+Q4+Q5+Q6 -> 750000
B7: 2 | C7: 유준일 | D7: 01024168843 | E7: 32503160 | F7: 4 | G7: =IF(IFERROR(VLOOKUP($F7,$P:$P,1,1),0)>=G$2,"o","-") -> o | H7: =IF(IFERROR(VLOOKUP($F7,$P:$P,1,1),0)>=H$2,"o","-") -> o | I7: =IF(IFERROR(VLOOKUP($F7,$P:$P,1,1),0)>=I$2,"o","-") -> - | J7: =IF(IFERROR(VLOOKUP($F7,$P:$P,1,1),0)>=J$2,"o","-") -> - | K7: =IF(IFERROR(VLOOKUP($F7,$P:$P,1,1),0)>=K$2,"o","-") -> - | L7: =IF(IFERROR(VLOOKUP($F7,$P:$P,1,1),0)>=L$2,"o","-") -> - | M7: =IF(IFERROR(VLOOKUP($F7,$P:$P,1,1),0)>=M$2,"o","-") -> - | N7: =IFERROR(VLOOKUP(F7,$P:$R,3,1),0) -> 150000 | P7: 10 | Q7: 600000 | R7: =Q3+Q4+Q5+Q6+Q7 -> 1350000
B8: 3 | C8: 박가희 | D8: 01062667163 | E8: 41100347 | F8: 4 | G8: =IF(IFERROR(VLOOKUP($F8,$P:$P,1,1),0)>=G$2,"o","-") -> o | H8: =IF(IFERROR(VLOOKUP($F8,$P:$P,1,1),0)>=H$2,"o","-") -> o | I8: =IF(IFERROR(VLOOKUP($F8,$P:$P,1,1),0)>=I$2,"o","-") -> - | J8: =IF(IFERROR(VLOOKUP($F8,$P:$P,1,1),0)>=J$2,"o","-") -> - | K8: =IF(IFERROR(VLOOKUP($F8,$P:$P,1,1),0)>=K$2,"o","-") -> - | L8: =IF(IFERROR(VLOOKUP($F8,$P:$P,1,1),0)>=L$2,"o","-") -> - | M8: =IF(IFERROR(VLOOKUP($F8,$P:$P,1,1),0)>=M$2,"o","-") -> - | N8: =IFERROR(VLOOKUP(F8,$P:$R,3,1),0) -> 150000 | P8: 15 | Q8: 1000000 | R8: =Q3+Q4+Q5+Q6+Q7+Q8 -> 2350000
B9: 4 | C9: 박자민 | D9: 01033267475 | E9: 42000464 | F9: 4 | G9: =IF(IFERROR(VLOOKUP($F9,$P:$P,1,1),0)>=G$2,"o","-") -> o | H9: =IF(IFERROR(VLOOKUP($F9,$P:$P,1,1),0)>=H$2,"o","-") -> o | I9: =IF(IFERROR(VLOOKUP($F9,$P:$P,1,1),0)>=I$2,"o","-") -> - | J9: =IF(IFERROR(VLOOKUP($F9,$P:$P,1,1),0)>=J$2,"o","-") -> - | K9: =IF(IFERROR(VLOOKUP($F9,$P:$P,1,1),0)>=K$2,"o","-") -> - | L9: =IF(IFERROR(VLOOKUP($F9,$P:$P,1,1),0)>=L$2,"o","-") -> - | M9: =IF(IFERROR(VLOOKUP($F9,$P:$P,1,1),0)>=M$2,"o","-") -> - | N9: =IFERROR(VLOOKUP(F9,$P:$R,3,1),0) -> 150000 | P9: 20 | Q9: 2000000 | R9: =Q3+Q4+Q5+Q6+Q7+Q8+Q9 -> 4350000
B10: 5 | C10: 장예리 | D10: 01042194914 | E10: 42302838 | F10: 4 | G10: =IF(IFERROR(VLOOKUP($F10,$P:$P,1,1),0)>=G$2,"o","-") -> o | H10: =IF(IFERROR(VLOOKUP($F10,$P:$P,1,1),0)>=H$2,"o","-") -> o | I10: =IF(IFERROR(VLOOKUP($F10,$P:$P,1,1),0)>=I$2,"o","-") -> - | J10: =IF(IFERROR(VLOOKUP($F10,$P:$P,1,1),0)>=J$2,"o","-") -> - | K10: =IF(IFERROR(VLOOKUP($F10,$P:$P,1,1),0)>=K$2,"o","-") -> - | L10: =IF(IFERROR(VLOOKUP($F10,$P:$P,1,1),0)>=L$2,"o","-") -> - | M10: =IF(IFERROR(VLOOKUP($F10,$P:$P,1,1),0)>=M$2,"o","-") -> - | N10: =IFERROR(VLOOKUP(F10,$P:$R,3,1),0) -> 150000
B11: 6 | C11: 이소희 | D11: 01027338936 | E11: 41601954 | F11: 4 | G11: =IF(IFERROR(VLOOKUP($F11,$P:$P,1,1),0)>=G$2,"o","-") -> o | H11: =IF(IFERROR(VLOOKUP($F11,$P:$P,1,1),0)>=H$2,"o","-") -> o | I11: =IF(IFERROR(VLOOKUP($F11,$P:$P,1,1),0)>=I$2,"o","-") -> - | J11: =IF(IFERROR(VLOOKUP($F11,$P:$P,1,1),0)>=J$2,"o","-") -> - | K11: =IF(IFERROR(VLOOKUP($F11,$P:$P,1,1),0)>=K$2,"o","-") -> - | L11: =IF(IFERROR(VLOOKUP($F11,$P:$P,1,1),0)>=L$2,"o","-") -> - | M11: =IF(IFERROR(VLOOKUP($F11,$P:$P,1,1),0)>=M$2,"o","-") -> - | N11: =IFERROR(VLOOKUP(F11,$P:$R,3,1),0) -> 150000
B12: 7 | C12: 김수현 | D12: 01094859695 | E12: 40709172 | F12: 4 | G12: =IF(IFERROR(VLOOKUP($F12,$P:$P,1,1),0)>=G$2,"o","-") -> o | H12: =IF(IFERROR(VLOOKUP($F12,$P:$P,1,1),0)>=H$2,"o","-") -> o | I12: =IF(IFERROR(VLOOKUP($F12,$P:$P,1,1),0)>=I$2,"o","-") -> - | J12: =IF(IFERROR(VLOOKUP($F12,$P:$P,1,1),0)>=J$2,"o","-") -> - | K12: =IF(IFERROR(VLOOKUP($F12,$P:$P,1,1),0)>=K$2,"o","-") -> - | L12: =IF(IFERROR(VLOOKUP($F12,$P:$P,1,1),0)>=L$2,"o","-") -> - | M12: =IF(IFERROR(VLOOKUP($F12,$P:$P,1,1),0)>=M$2,"o","-") -> - | N12: =IFERROR(VLOOKUP(F12,$P:$R,3,1),0) -> 150000
B13: 8 | C13: 류민지 | D13: 01066844589 | E13: 41605446 | F13: 4 | G13: =IF(IFERROR(VLOOKUP($F13,$P:$P,1,1),0)>=G$2,"o","-") -> o | H13: =IF(IFERROR(VLOOKUP($F13,$P:$P,1,1),0)>=H$2,"o","-") -> o | I13: =IF(IFERROR(VLOOKUP($F13,$P:$P,1,1),0)>=I$2,"o","-") -> - | J13: =IF(IFERROR(VLOOKUP($F13,$P:$P,1,1),0)>=J$2,"o","-") -> - | K13: =IF(IFERROR(VLOOKUP($F13,$P:$P,1,1),0)>=K$2,"o","-") -> - | L13: =IF(IFERROR(VLOOKUP($F13,$P:$P,1,1),0)>=L$2,"o","-") -> - | M13: =IF(IFERROR(VLOOKUP($F13,$P:$P,1,1),0)>=M$2,"o","-") -> - | N13: =IFERROR(VLOOKUP(F13,$P:$R,3,1),0) -> 150000
B14: 9 | C14: 성다은 | D14: 01029279218 | E14: 41805372 | F14: 4 | G14: =IF(IFERROR(VLOOKUP($F14,$P:$P,1,1),0)>=G$2,"o","-") -> o | H14: =IF(IFERROR(VLOOKUP($F14,$P:$P,1,1),0)>=H$2,"o","-") -> o | I14: =IF(IFERROR(VLOOKUP($F14,$P:$P,1,1),0)>=I$2,"o","-") -> - | J14: =IF(IFERROR(VLOOKUP($F14,$P:$P,1,1),0)>=J$2,"o","-") -> - | K14: =IF(IFERROR(VLOOKUP($F14,$P:$P,1,1),0)>=K$2,"o","-") -> - | L14: =IF(IFERROR(VLOOKUP($F14,$P:$P,1,1),0)>=L$2,"o","-") -> - | M14: =IF(IFERROR(VLOOKUP($F14,$P:$P,1,1),0)>=M$2,"o","-") -> - | N14: =IFERROR(VLOOKUP(F14,$P:$R,3,1),0) -> 150000
B15: 10 | C15: 박지원 | D15: 01087685824 | E15: 42402189 | F15: 4 | G15: =IF(IFERROR(VLOOKUP($F15,$P:$P,1,1),0)>=G$2,"o","-") -> o | H15: =IF(IFERROR(VLOOKUP($F15,$P:$P,1,1),0)>=H$2,"o","-") -> o | I15: =IF(IFERROR(VLOOKUP($F15,$P:$P,1,1),0)>=I$2,"o","-") -> - | J15: =IF(IFERROR(VLOOKUP($F15,$P:$P,1,1),0)>=J$2,"o","-") -> - | K15: =IF(IFERROR(VLOOKUP($F15,$P:$P,1,1),0)>=K$2,"o","-") -> - | L15: =IF(IFERROR(VLOOKUP($F15,$P:$P,1,1),0)>=L$2,"o","-") -> - | M15: =IF(IFERROR(VLOOKUP($F15,$P:$P,1,1),0)>=M$2,"o","-") -> - | N15: =IFERROR(VLOOKUP(F15,$P:$R,3,1),0) -> 150000
B16: 11 | C16: 박소민 | D16: 01020894759 | E16: 42201254 | F16: 2 | G16: =IF(IFERROR(VLOOKUP($F16,$P:$P,1,1),0)>=G$2,"o","-") -> o | H16: =IF(IFERROR(VLOOKUP($F16,$P:$P,1,1),0)>=H$2,"o","-") -> - | I16: =IF(IFERROR(VLOOKUP($F16,$P:$P,1,1),0)>=I$2,"o","-") -> - | J16: =IF(IFERROR(VLOOKUP($F16,$P:$P,1,1),0)>=J$2,"o","-") -> - | K16: =IF(IFERROR(VLOOKUP($F16,$P:$P,1,1),0)>=K$2,"o","-") -> - | L16: =IF(IFERROR(VLOOKUP($F16,$P:$P,1,1),0)>=L$2,"o","-") -> - | M16: =IF(IFERROR(VLOOKUP($F16,$P:$P,1,1),0)>=M$2,"o","-") -> - | N16: =IFERROR(VLOOKUP(F16,$P:$R,3,1),0) -> 50000
B17: 12 | C17: 오세훈 | D17: 01074549229 | E17: 31600514 | F17: 2 | G17: =IF(IFERROR(VLOOKUP($F17,$P:$P,1,1),0)>=G$2,"o","-") -> o | H17: =IF(IFERROR(VLOOKUP($F17,$P:$P,1,1),0)>=H$2,"o","-") -> - | I17: =IF(IFERROR(VLOOKUP($F17,$P:$P,1,1),0)>=I$2,"o","-") -> - | J17: =IF(IFERROR(VLOOKUP($F17,$P:$P,1,1),0)>=J$2,"o","-") -> - | K17: =IF(IFERROR(VLOOKUP($F17,$P:$P,1,1),0)>=K$2,"o","-") -> - | L17: =IF(IFERROR(VLOOKUP($F17,$P:$P,1,1),0)>=L$2,"o","-") -> - | M17: =IF(IFERROR(VLOOKUP($F17,$P:$P,1,1),0)>=M$2,"o","-") -> - | N17: =IFERROR(VLOOKUP(F17,$P:$R,3,1),0) -> 50000
B18: 13 | C18: 오상준 | D18: 01074551980 | E18: 32500451 | F18: 2 | G18: =IF(IFERROR(VLOOKUP($F18,$P:$P,1,1),0)>=G$2,"o","-") -> o | H18: =IF(IFERROR(VLOOKUP($F18,$P:$P,1,1),0)>=H$2,"o","-") -> - | I18: =IF(IFERROR(VLOOKUP($F18,$P:$P,1,1),0)>=I$2,"o","-") -> - | J18: =IF(IFERROR(VLOOKUP($F18,$P:$P,1,1),0)>=J$2,"o","-") -> - | K18: =IF(IFERROR(VLOOKUP($F18,$P:$P,1,1),0)>=K$2,"o","-") -> - | L18: =IF(IFERROR(VLOOKUP($F18,$P:$P,1,1),0)>=L$2,"o","-") -> - | M18: =IF(IFERROR(VLOOKUP($F18,$P:$P,1,1),0)>=M$2,"o","-") -> - | N18: =IFERROR(VLOOKUP(F18,$P:$R,3,1),0) -> 50000
B19: 14 | C19: 이다영 | D19: 01031341531 | E19: 42000824 | F19: 2 | G19: =IF(IFERROR(VLOOKUP($F19,$P:$P,1,1),0)>=G$2,"o","-") -> o | H19: =IF(IFERROR(VLOOKUP($F19,$P:$P,1,1),0)>=H$2,"o","-") -> - | I19: =IF(IFERROR(VLOOKUP($F19,$P:$P,1,1),0)>=I$2,"o","-") -> - | J19: =IF(IFERROR(VLOOKUP($F19,$P:$P,1,1),0)>=J$2,"o","-") -> - | K19: =IF(IFERROR(VLOOKUP($F19,$P:$P,1,1),0)>=K$2,"o","-") -> - | L19: =IF(IFERROR(VLOOKUP($F19,$P:$P,1,1),0)>=L$2,"o","-") -> - | M19: =IF(IFERROR(VLOOKUP($F19,$P:$P,1,1),0)>=M$2,"o","-") -> - | N19: =IFERROR(VLOOKUP(F19,$P:$R,3,1),0) -> 50000 | P19: [우리카드]
B20: 15 | C20: 안동환 | D20: 01065929022 | E20: 31903040 | F20: 2 | G20: =IF(IFERROR(VLOOKUP($F20,$P:$P,1,1),0)>=G$2,"o","-") -> o | H20: =IF(IFERROR(VLOOKUP($F20,$P:$P,1,1),0)>=H$2,"o","-") -> - | I20: =IF(IFERROR(VLOOKUP($F20,$P:$P,1,1),0)>=I$2,"o","-") -> - | J20: =IF(IFERROR(VLOOKUP($F20,$P:$P,1,1),0)>=J$2,"o","-") -> - | K20: =IF(IFERROR(VLOOKUP($F20,$P:$P,1,1),0)>=K$2,"o","-") -> - | L20: =IF(IFERROR(VLOOKUP($F20,$P:$P,1,1),0)>=L$2,"o","-") -> - | M20: =IF(IFERROR(VLOOKUP($F20,$P:$P,1,1),0)>=M$2,"o","-") -> - | N20: =IFERROR(VLOOKUP(F20,$P:$R,3,1),0) -> 50000 | P20: 법인사업자 기업카드 모집에 힘써주셔서 감사합니다.
B21: 16 | C21: 구민기 | D21: 01094989823 | E21: 32406177 | F21: 2 | G21: =IF(IFERROR(VLOOKUP($F21,$P:$P,1,1),0)>=G$2,"o","-") -> o | H21: =IF(IFERROR(VLOOKUP($F21,$P:$P,1,1),0)>=H$2,"o","-") -> - | I21: =IF(IFERROR(VLOOKUP($F21,$P:$P,1,1),0)>=I$2,"o","-") -> - | J21: =IF(IFERROR(VLOOKUP($F21,$P:$P,1,1),0)>=J$2,"o","-") -> - | K21: =IF(IFERROR(VLOOKUP($F21,$P:$P,1,1),0)>=K$2,"o","-") -> - | L21: =IF(IFERROR(VLOOKUP($F21,$P:$P,1,1),0)>=L$2,"o","-") -> - | M21: =IF(IFERROR(VLOOKUP($F21,$P:$P,1,1),0)>=M$2,"o","-") -> - | N21: =IFERROR(VLOOKUP(F21,$P:$R,3,1),0) -> 50000 | P21: 첨부된 url 통해 원하시는 상품 골라주세요!
B22: 17 | C22: 김현정 | D22: 01083011145 | E22: 40604330 | F22: 2 | G22: =IF(IFERROR(VLOOKUP($F22,$P:$P,1,1),0)>=G$2,"o","-") -> o | H22: =IF(IFERROR(VLOOKUP($F22,$P:$P,1,1),0)>=H$2,"o","-") -> - | I22: =IF(IFERROR(VLOOKUP($F22,$P:$P,1,1),0)>=I$2,"o","-") -> - | J22: =IF(IFERROR(VLOOKUP($F22,$P:$P,1,1),0)>=J$2,"o","-") -> - | K22: =IF(IFERROR(VLOOKUP($F22,$P:$P,1,1),0)>=K$2,"o","-") -> - | L22: =IF(IFERROR(VLOOKUP($F22,$P:$P,1,1),0)>=L$2,"o","-") -> - | M22: =IF(IFERROR(VLOOKUP($F22,$P:$P,1,1),0)>=M$2,"o","-") -> - | N22: =IFERROR(VLOOKUP(F22,$P:$R,3,1),0) -> 50000
B23: 18 | C23: 이승종 | D23: 01093310873 | E23: 31804446 | F23: 2 | G23: =IF(IFERROR(VLOOKUP($F23,$P:$P,1,1),0)>=G$2,"o","-") -> o | H23: =IF(IFERROR(VLOOKUP($F23,$P:$P,1,1),0)>=H$2,"o","-") -> - | I23: =IF(IFERROR(VLOOKUP($F23,$P:$P,1,1),0)>=I$2,"o","-") -> - | J23: =IF(IFERROR(VLOOKUP($F23,$P:$P,1,1),0)>=J$2,"o","-") -> - | K23: =IF(IFERROR(VLOOKUP($F23,$P:$P,1,1),0)>=K$2,"o","-") -> - | L23: =IF(IFERROR(VLOOKUP($F23,$P:$P,1,1),0)>=L$2,"o","-") -> - | M23: =IF(IFERROR(VLOOKUP($F23,$P:$P,1,1),0)>=M$2,"o","-") -> - | N23: =IFERROR(VLOOKUP(F23,$P:$R,3,1),0) -> 50000 | P23: 한번이 아니라 더더더 좋은걸로 계속드립니다!!
B24: 19 | C24: 장소영 | D24: 01049013169 | E24: 41507265 | F24: 2 | G24: =IF(IFERROR(VLOOKUP($F24,$P:$P,1,1),0)>=G$2,"o","-") -> o | H24: =IF(IFERROR(VLOOKUP($F24,$P:$P,1,1),0)>=H$2,"o","-") -> - | I24: =IF(IFERROR(VLOOKUP($F24,$P:$P,1,1),0)>=I$2,"o","-") -> - | J24: =IF(IFERROR(VLOOKUP($F24,$P:$P,1,1),0)>=J$2,"o","-") -> - | K24: =IF(IFERROR(VLOOKUP($F24,$P:$P,1,1),0)>=K$2,"o","-") -> - | L24: =IF(IFERROR(VLOOKUP($F24,$P:$P,1,1),0)>=L$2,"o","-") -> - | M24: =IF(IFERROR(VLOOKUP($F24,$P:$P,1,1),0)>=M$2,"o","-") -> - | N24: =IFERROR(VLOOKUP(F24,$P:$R,3,1),0) -> 50000 | P24: 법인 신규모집 구간 달성할 때마다 포상 받아가세요! (이미지 참고)
B25: 20 | C25: 안세혁 | D25: 01022807858 | E25: 31504061 | F25: 2 | G25: =IF(IFERROR(VLOOKUP($F25,$P:$P,1,1),0)>=G$2,"o","-") -> o | H25: =IF(IFERROR(VLOOKUP($F25,$P:$P,1,1),0)>=H$2,"o","-") -> - | I25: =IF(IFERROR(VLOOKUP($F25,$P:$P,1,1),0)>=I$2,"o","-") -> - | J25: =IF(IFERROR(VLOOKUP($F25,$P:$P,1,1),0)>=J$2,"o","-") -> - | K25: =IF(IFERROR(VLOOKUP($F25,$P:$P,1,1),0)>=K$2,"o","-") -> - | L25: =IF(IFERROR(VLOOKUP($F25,$P:$P,1,1),0)>=L$2,"o","-") -> - | M25: =IF(IFERROR(VLOOKUP($F25,$P:$P,1,1),0)>=M$2,"o","-") -> - | N25: =IFERROR(VLOOKUP(F25,$P:$R,3,1),0) -> 50000
B26: 21 | C26: 이상민 | D26: 01029306445 | E26: 32002544 | F26: 2 | G26: =IF(IFERROR(VLOOKUP($F26,$P:$P,1,1),0)>=G$2,"o","-") -> o | H26: =IF(IFERROR(VLOOKUP($F26,$P:$P,1,1),0)>=H$2,"o","-") -> - | I26: =IF(IFERROR(VLOOKUP($F26,$P:$P,1,1),0)>=I$2,"o","-") -> - | J26: =IF(IFERROR(VLOOKUP($F26,$P:$P,1,1),0)>=J$2,"o","-") -> - | K26: =IF(IFERROR(VLOOKUP($F26,$P:$P,1,1),0)>=K$2,"o","-") -> - | L26: =IF(IFERROR(VLOOKUP($F26,$P:$P,1,1),0)>=L$2,"o","-") -> - | M26: =IF(IFERROR(VLOOKUP($F26,$P:$P,1,1),0)>=M$2,"o","-") -> - | N26: =IFERROR(VLOOKUP(F26,$P:$R,3,1),0) -> 50000
B27: 22 | C27: 맹현 | D27: 01041177989 | E27: 32408841 | F27: 2 | G27: =IF(IFERROR(VLOOKUP($F27,$P:$P,1,1),0)>=G$2,"o","-") -> o | H27: =IF(IFERROR(VLOOKUP($F27,$P:$P,1,1),0)>=H$2,"o","-") -> - | I27: =IF(IFERROR(VLOOKUP($F27,$P:$P,1,1),0)>=I$2,"o","-") -> - | J27: =IF(IFERROR(VLOOKUP($F27,$P:$P,1,1),0)>=J$2,"o","-") -> - | K27: =IF(IFERROR(VLOOKUP($F27,$P:$P,1,1),0)>=K$2,"o","-") -> - | L27: =IF(IFERROR(VLOOKUP($F27,$P:$P,1,1),0)>=L$2,"o","-") -> - | M27: =IF(IFERROR(VLOOKUP($F27,$P:$P,1,1),0)>=M$2,"o","-") -> - | N27: =IFERROR(VLOOKUP(F27,$P:$R,3,1),0) -> 50000
B28: 23 | C28: 김미연 | D28: 01099370290 | E28: 41900231 | F28: 2 | G28: =IF(IFERROR(VLOOKUP($F28,$P:$P,1,1),0)>=G$2,"o","-") -> o | H28: =IF(IFERROR(VLOOKUP($F28,$P:$P,1,1),0)>=H$2,"o","-") -> - | I28: =IF(IFERROR(VLOOKUP($F28,$P:$P,1,1),0)>=I$2,"o","-") -> - | J28: =IF(IFERROR(VLOOKUP($F28,$P:$P,1,1),0)>=J$2,"o","-") -> - | K28: =IF(IFERROR(VLOOKUP($F28,$P:$P,1,1),0)>=K$2,"o","-") -> - | L28: =IF(IFERROR(VLOOKUP($F28,$P:$P,1,1),0)>=L$2,"o","-") -> - | M28: =IF(IFERROR(VLOOKUP($F28,$P:$P,1,1),0)>=M$2,"o","-") -> - | N28: =IFERROR(VLOOKUP(F28,$P:$R,3,1),0) -> 50000
B29: 24 | C29: 최진경 | D29: 01030161987 | E29: 41000618 | F29: 2 | G29: =IF(IFERROR(VLOOKUP($F29,$P:$P,1,1),0)>=G$2,"o","-") -> o | H29: =IF(IFERROR(VLOOKUP($F29,$P:$P,1,1),0)>=H$2,"o","-") -> - | I29: =IF(IFERROR(VLOOKUP($F29,$P:$P,1,1),0)>=I$2,"o","-") -> - | J29: =IF(IFERROR(VLOOKUP($F29,$P:$P,1,1),0)>=J$2,"o","-") -> - | K29: =IF(IFERROR(VLOOKUP($F29,$P:$P,1,1),0)>=K$2,"o","-") -> - | L29: =IF(IFERROR(VLOOKUP($F29,$P:$P,1,1),0)>=L$2,"o","-") -> - | M29: =IF(IFERROR(VLOOKUP($F29,$P:$P,1,1),0)>=M$2,"o","-") -> - | N29: =IFERROR(VLOOKUP(F29,$P:$R,3,1),0) -> 50000
B30: 25 | C30: 이초롱 | D30: 01039047043 | E30: 40800549 | F30: 2 | G30: =IF(IFERROR(VLOOKUP($F30,$P:$P,1,1),0)>=G$2,"o","-") -> o | H30: =IF(IFERROR(VLOOKUP($F30,$P:$P,1,1),0)>=H$2,"o","-") -> - | I30: =IF(IFERROR(VLOOKUP($F30,$P:$P,1,1),0)>=I$2,"o","-") -> - | J30: =IF(IFERROR(VLOOKUP($F30,$P:$P,1,1),0)>=J$2,"o","-") -> - | K30: =IF(IFERROR(VLOOKUP($F30,$P:$P,1,1),0)>=K$2,"o","-") -> - | L30: =IF(IFERROR(VLOOKUP($F30,$P:$P,1,1),0)>=L$2,"o","-") -> - | M30: =IF(IFERROR(VLOOKUP($F30,$P:$P,1,1),0)>=M$2,"o","-") -> - | N30: =IFERROR(VLOOKUP(F30,$P:$R,3,1),0) -> 50000
B31: 26 | C31: 김도희 | D31: 01042322460 | E31: 41300129 | F31: 2 | G31: =IF(IFERROR(VLOOKUP($F31,$P:$P,1,1),0)>=G$2,"o","-") -> o | H31: =IF(IFERROR(VLOOKUP($F31,$P:$P,1,1),0)>=H$2,"o","-") -> - | I31: =IF(IFERROR(VLOOKUP($F31,$P:$P,1,1),0)>=I$2,"o","-") -> - | J31: =IF(IFERROR(VLOOKUP($F31,$P:$P,1,1),0)>=J$2,"o","-") -> - | K31: =IF(IFERROR(VLOOKUP($F31,$P:$P,1,1),0)>=K$2,"o","-") -> - | L31: =IF(IFERROR(VLOOKUP($F31,$P:$P,1,1),0)>=L$2,"o","-") -> - | M31: =IF(IFERROR(VLOOKUP($F31,$P:$P,1,1),0)>=M$2,"o","-") -> - | N31: =IFERROR(VLOOKUP(F31,$P:$R,3,1),0) -> 50000
B32: 27 | C32: 박서현 | D32: 01042394199 | E32: 42201245 | F32: 2 | G32: =IF(IFERROR(VLOOKUP($F32,$P:$P,1,1),0)>=G$2,"o","-") -> o | H32: =IF(IFERROR(VLOOKUP($F32,$P:$P,1,1),0)>=H$2,"o","-") -> - | I32: =IF(IFERROR(VLOOKUP($F32,$P:$P,1,1),0)>=I$2,"o","-") -> - | J32: =IF(IFERROR(VLOOKUP($F32,$P:$P,1,1),0)>=J$2,"o","-") -> - | K32: =IF(IFERROR(VLOOKUP($F32,$P:$P,1,1),0)>=K$2,"o","-") -> - | L32: =IF(IFERROR(VLOOKUP($F32,$P:$P,1,1),0)>=L$2,"o","-") -> - | M32: =IF(IFERROR(VLOOKUP($F32,$P:$P,1,1),0)>=M$2,"o","-") -> - | N32: =IFERROR(VLOOKUP(F32,$P:$R,3,1),0) -> 50000
B33: 28 | C33: 이원준 | D33: 01023803799 | E33: 32409200 | F33: 2 | G33: =IF(IFERROR(VLOOKUP($F33,$P:$P,1,1),0)>=G$2,"o","-") -> o | H33: =IF(IFERROR(VLOOKUP($F33,$P:$P,1,1),0)>=H$2,"o","-") -> - | I33: =IF(IFERROR(VLOOKUP($F33,$P:$P,1,1),0)>=I$2,"o","-") -> - | J33: =IF(IFERROR(VLOOKUP($F33,$P:$P,1,1),0)>=J$2,"o","-") -> - | K33: =IF(IFERROR(VLOOKUP($F33,$P:$P,1,1),0)>=K$2,"o","-") -> - | L33: =IF(IFERROR(VLOOKUP($F33,$P:$P,1,1),0)>=L$2,"o","-") -> - | M33: =IF(IFERROR(VLOOKUP($F33,$P:$P,1,1),0)>=M$2,"o","-") -> - | N33: =IFERROR(VLOOKUP(F33,$P:$R,3,1),0) -> 50000
B34: 29 | C34: 박동빈 | D34: 01033699448 | E34: 32408904 | F34: 2 | G34: =IF(IFERROR(VLOOKUP($F34,$P:$P,1,1),0)>=G$2,"o","-") -> o | H34: =IF(IFERROR(VLOOKUP($F34,$P:$P,1,1),0)>=H$2,"o","-") -> - | I34: =IF(IFERROR(VLOOKUP($F34,$P:$P,1,1),0)>=I$2,"o","-") -> - | J34: =IF(IFERROR(VLOOKUP($F34,$P:$P,1,1),0)>=J$2,"o","-") -> - | K34: =IF(IFERROR(VLOOKUP($F34,$P:$P,1,1),0)>=K$2,"o","-") -> - | L34: =IF(IFERROR(VLOOKUP($F34,$P:$P,1,1),0)>=L$2,"o","-") -> - | M34: =IF(IFERROR(VLOOKUP($F34,$P:$P,1,1),0)>=M$2,"o","-") -> - | N34: =IFERROR(VLOOKUP(F34,$P:$R,3,1),0) -> 50000
B35: 30 | C35: 이진영 | D35: 01073352427 | E35: 41900899 | F35: 2 | G35: =IF(IFERROR(VLOOKUP($F35,$P:$P,1,1),0)>=G$2,"o","-") -> o | H35: =IF(IFERROR(VLOOKUP($F35,$P:$P,1,1),0)>=H$2,"o","-") -> - | I35: =IF(IFERROR(VLOOKUP($F35,$P:$P,1,1),0)>=I$2,"o","-") -> - | J35: =IF(IFERROR(VLOOKUP($F35,$P:$P,1,1),0)>=J$2,"o","-") -> - | K35: =IF(IFERROR(VLOOKUP($F35,$P:$P,1,1),0)>=K$2,"o","-") -> - | L35: =IF(IFERROR(VLOOKUP($F35,$P:$P,1,1),0)>=L$2,"o","-") -> - | M35: =IF(IFERROR(VLOOKUP($F35,$P:$P,1,1),0)>=M$2,"o","-") -> - | N35: =IFERROR(VLOOKUP(F35,$P:$R,3,1),0) -> 50000
B36: 31 | C36: 조용석 | D36: 01066350582 | E36: 32407031 | F36: 2 | G36: =IF(IFERROR(VLOOKUP($F36,$P:$P,1,1),0)>=G$2,"o","-") -> o | H36: =IF(IFERROR(VLOOKUP($F36,$P:$P,1,1),0)>=H$2,"o","-") -> - | I36: =IF(IFERROR(VLOOKUP($F36,$P:$P,1,1),0)>=I$2,"o","-") -> - | J36: =IF(IFERROR(VLOOKUP($F36,$P:$P,1,1),0)>=J$2,"o","-") -> - | K36: =IF(IFERROR(VLOOKUP($F36,$P:$P,1,1),0)>=K$2,"o","-") -> - | L36: =IF(IFERROR(VLOOKUP($F36,$P:$P,1,1),0)>=L$2,"o","-") -> - | M36: =IF(IFERROR(VLOOKUP($F36,$P:$P,1,1),0)>=M$2,"o","-") -> - | N36: =IFERROR(VLOOKUP(F36,$P:$R,3,1),0) -> 50000
... B194: 189 | C194: 이민정 | D194: 01088541493 | E194: 41206359 | F194: 2 | G194: =IF(IFERROR(VLOOKUP($F194,$P:$P,1,1),0)>=G$2,"o","-") -> o | H194: =IF(IFERROR(VLOOKUP($F194,$P:$P,1,1),0)>=H$2,"o","-") -> - | I194: =IF(IFERROR(VLOOKUP($F194,$P:$P,1,1),0)>=I$2,"o","-") -> - | J194: =IF(IFERROR(VLOOKUP($F194,$P:$P,1,1),0)>=J$2,"o","-") -> - | K194: =IF(IFERROR(VLOOKUP($F194,$P:$P,1,1),0)>=K$2,"o","-") -> - | L194: =IF(IFERROR(VLOOKUP($F194,$P:$P,1,1),0)>=L$2,"o","-") -> - | M194: =IF(IFERROR(VLOOKUP($F194,$P:$P,1,1),0)>=M$2,"o","-") -> - | N194: =IFERROR(VLOOKUP(F194,$P:$R,3,1),0) -> 50000

Sheet 2월
B1: ■ 우리카드 구간포상 이벤트_202602
L2: 2 | M2: 4 | N2: 6 | O2: 8 | P2: 10 | Q2: 15 | R2: 20
B3: 구분 | C3: 이름 | D3: 휴대폰번호 | E3: 행번 | F3: 달성구간 | L3: 포상 | U3: 2 | V3: 50000 | W3: =V3 -> 50000
F4: 1월 | G4: 2월 | H4: 3월 | I4: 4월 | J4: 5월 | K4: 6월 | L4: 2좌 | M4: 4좌 | N4: 6좌 | O4: 8좌 | P4: 10좌 | Q4: 15좌 | R4: 20좌 | S4: 총액 | U4: 4 | V4: 100000 | W4: =V3+V4 -> 150000
C5: 합계 | D5: =COUNTA(C6:C194) -> 189 | L5: =COUNTIFS(L6:L9999,"o") -> 246 | M5: =COUNTIFS(M6:M9999,"o") -> 80 | N5: =COUNTIFS(N6:N9999,"o") -> 11 | O5: =COUNTIFS(O6:O9999,"o") -> 2 | P5: =COUNTIFS(P6:P9999,"o") -> 0 | Q5: =COUNTIFS(Q6:Q9999,"o") -> 0 | R5: =COUNTIFS(R6:R9999,"o") -> 0 | S5: =SUM(S6:S9999) -> 23300000 | U5: 6 | V5: 200000 | W5: =V3+V4+V5 -> 350000
B6: 1 | C6: 안동환 | D6: 01065929022 | E6: 31903040 | F6: =IFERROR(VLOOKUP(D6,'1월'!D:F,3,0),) -> 2 | G6: 8 | L6: =IF($F6>=L$2,"-",IF(IFERROR(VLOOKUP($G6,$U:$U,1,1),0)>=L$2,"o","-")) -> - | M6: =IF($F6>=M$2,"-",IF(IFERROR(VLOOKUP($G6,$U:$U,1,1),0)>=M$2,"o","-")) -> o | N6: =IF($F6>=N$2,"-",IF(IFERROR(VLOOKUP($G6,$U:$U,1,1),0)>=N$2,"o","-")) -> o | O6: =IF($F6>=O$2,"-",IF(IFERROR(VLOOKUP($G6,$U:$U,1,1),0)>=O$2,"o","-")) -> o | P6: =IF($F6>=P$2,"-",IF(IFERROR(VLOOKUP($G6,$U:$U,1,1),0)>=P$2,"o","-")) -> - | Q6: =IF($F6>=Q$2,"-",IF(IFERROR(VLOOKUP($G6,$U:$U,1,1),0)>=Q$2,"o","-")) -> - | R6: =IF($F6>=R$2,"-",IF(IFERROR(VLOOKUP($G6,$U:$U,1,1),0)>=R$2,"o","-")) -> - | S6: =IF(L6="o",50000,0)+IF(M6="o",100000,0)+IF(N6="o",200000,0)+IF(O6="o",400000,0)+IF(P6="o",600000,0)+IF(Q6="o",1000000,0)+IF(R6="o",2000000,0) -> 700000 | U6: 8 | V6: 400000 | W6: =V3+V4+V5+V6 -> 750000
B7: 2 | C7: 서동환 | D7: 01079271992 | E7: 31902942 | F7: =IFERROR(VLOOKUP(D7,'1월'!D:F,3,0),) -> 6 | G7: 8 | L7: =IF($F7>=L$2,"-",IF(IFERROR(VLOOKUP($G7,$U:$U,1,1),0)>=L$2,"o","-")) -> - | M7: =IF($F7>=M$2,"-",IF(IFERROR(VLOOKUP($G7,$U:$U,1,1),0)>=M$2,"o","-")) -> - | N7: =IF($F7>=N$2,"-",IF(IFERROR(VLOOKUP($G7,$U:$U,1,1),0)>=N$2,"o","-")) -> - | O7: =IF($F7>=O$2,"-",IF(IFERROR(VLOOKUP($G7,$U:$U,1,1),0)>=O$2,"o","-")) -> o | P7: =IF($F7>=P$2,"-",IF(IFERROR(VLOOKUP($G7,$U:$U,1,1),0)>=P$2,"o","-")) -> - | Q7: =IF($F7>=Q$2,"-",IF(IFERROR(VLOOKUP($G7,$U:$U,1,1),0)>=Q$2,"o","-")) -> - | R7: =IF($F7>=R$2,"-",IF(IFERROR(VLOOKUP($G7,$U:$U,1,1),0)>=R$2,"o","-")) -> - | S7: =IF(L7="o",50000,0)+IF(M7="o",100000,0)+IF(N7="o",200000,0)+IF(O7="o",400000,0)+IF(P7="o",600000,0)+IF(Q7="o",1000000,0)+IF(R7="o",2000000,0) -> 400000 | U7: 10 | V7: 600000 | W7: =V3+V4+V5+V6+V7 -> 1350000
B8: 3 | C8: 송혜원 | D8: 01040493155 | E8: 42201308 | F8: =IFERROR(VLOOKUP(D8,'1월'!D:F,3,0),) -> 0 | G8: 6 | L8: =IF($F8>=L$2,"-",IF(IFERROR(VLOOKUP($G8,$U:$U,1,1),0)>=L$2,"o","-")) -> o | M8: =IF($F8>=M$2,"-",IF(IFERROR(VLOOKUP($G8,$U:$U,1,1),0)>=M$2,"o","-")) -> o | N8: =IF($F8>=N$2,"-",IF(IFERROR(VLOOKUP($G8,$U:$U,1,1),0)>=N$2,"o","-")) -> o | O8: =IF($F8>=O$2,"-",IF(IFERROR(VLOOKUP($G8,$U:$U,1,1),0)>=O$2,"o","-")) -> - | P8: =IF($F8>=P$2,"-",IF(IFERROR(VLOOKUP($G8,$U:$U,1,1),0)>=P$2,"o","-")) -> - | Q8: =IF($F8>=Q$2,"-",IF(IFERROR(VLOOKUP($G8,$U:$U,1,1),0)>=Q$2,"o","-")) -> - | R8: =IF($F8>=R$2,"-",IF(IFERROR(VLOOKUP($G8,$U:$U,1,1),0)>=R$2,"o","-")) -> - | S8: =IF(L8="o",50000,0)+IF(M8="o",100000,0)+IF(N8="o",200000,0)+IF(O8="o",400000,0)+IF(P8="o",600000,0)+IF(Q8="o",1000000,0)+IF(R8="o",2000000,0) -> 350000 | U8: 15 | V8: 1000000 | W8: =V3+V4+V5+V6+V7+V8 -> 2350000
B9: 4 | C9: 윤덕상 | D9: 01095129328 | E9: 32406717 | F9: =IFERROR(VLOOKUP(D9,'1월'!D:F,3,0),) -> 0 | G9: 6 | L9: =IF($F9>=L$2,"-",IF(IFERROR(VLOOKUP($G9,$U:$U,1,1),0)>=L$2,"o","-")) -> o | M9: =IF($F9>=M$2,"-",IF(IFERROR(VLOOKUP($G9,$U:$U,1,1),0)>=M$2,"o","-")) -> o | N9: =IF($F9>=N$2,"-",IF(IFERROR(VLOOKUP($G9,$U:$U,1,1),0)>=N$2,"o","-")) -> o | O9: =IF($F9>=O$2,"-",IF(IFERROR(VLOOKUP($G9,$U:$U,1,1),0)>=O$2,"o","-")) -> - | P9: =IF($F9>=P$2,"-",IF(IFERROR(VLOOKUP($G9,$U:$U,1,1),0)>=P$2,"o","-")) -> - | Q9: =IF($F9>=Q$2,"-",IF(IFERROR(VLOOKUP($G9,$U:$U,1,1),0)>=Q$2,"o","-")) -> - | R9: =IF($F9>=R$2,"-",IF(IFERROR(VLOOKUP($G9,$U:$U,1,1),0)>=R$2,"o","-")) -> - | S9: =IF(L9="o",50000,0)+IF(M9="o",100000,0)+IF(N9="o",200000,0)+IF(O9="o",400000,0)+IF(P9="o",600000,0)+IF(Q9="o",1000000,0)+IF(R9="o",2000000,0) -> 350000 | U9: 20 | V9: 2000000 | W9: =V3+V4+V5+V6+V7+V8+V9 -> 4350000
B10: 5 | C10: 최예원 | D10: 01034379412 | E10: 41901041 | F10: =IFERROR(VLOOKUP(D10,'1월'!D:F,3,0),) -> 2 | G10: 6 | L10: =IF($F10>=L$2,"-",IF(IFERROR(VLOOKUP($G10,$U:$U,1,1),0)>=L$2,"o","-")) -> - | M10: =IF($F10>=M$2,"-",IF(IFERROR(VLOOKUP($G10,$U:$U,1,1),0)>=M$2,"o","-")) -> o | N10: =IF($F10>=N$2,"-",IF(IFERROR(VLOOKUP($G10,$U:$U,1,1),0)>=N$2,"o","-")) -> o | O10: =IF($F10>=O$2,"-",IF(IFERROR(VLOOKUP($G10,$U:$U,1,1),0)>=O$2,"o","-")) -> - | P10: =IF($F10>=P$2,"-",IF(IFERROR(VLOOKUP($G10,$U:$U,1,1),0)>=P$2,"o","-")) -> - | Q10: =IF($F10>=Q$2,"-",IF(IFERROR(VLOOKUP($G10,$U:$U,1,1),0)>=Q$2,"o","-")) -> - | R10: =IF($F10>=R$2,"-",IF(IFERROR(VLOOKUP($G10,$U:$U,1,1),0)>=R$2,"o","-")) -> - | S10: =IF(L10="o",50000,0)+IF(M10="o",100000,0)+IF(N10="o",200000,0)+IF(O10="o",400000,0)+IF(P10="o",600000,0)+IF(Q10="o",1000000,0)+IF(R10="o",2000000,0) -> 300000
B11: 6 | C11: 윤미진 | D11: 01048789184 | E11: 41304819 | F11: =IFERROR(VLOOKUP(D11,'1월'!D:F,3,0),) -> 2 | G11: 6 | L11: =IF($F11>=L$2,"-",IF(IFERROR(VLOOKUP($G11,$U:$U,1,1),0)>=L$2,"o","-")) -> - | M11: =IF($F11>=M$2,"-",IF(IFERROR(VLOOKUP($G11,$U:$U,1,1),0)>=M$2,"o","-")) -> o | N11: =IF($F11>=N$2,"-",IF(IFERROR(VLOOKUP($G11,$U:$U,1,1),0)>=N$2,"o","-")) -> o | O11: =IF($F11>=O$2,"-",IF(IFERROR(VLOOKUP($G11,$U:$U,1,1),0)>=O$2,"o","-")) -> - | P11: =IF($F11>=P$2,"-",IF(IFERROR(VLOOKUP($G11,$U:$U,1,1),0)>=P$2,"o","-")) -> - | Q11: =IF($F11>=Q$2,"-",IF(IFERROR(VLOOKUP($G11,$U:$U,1,1),0)>=Q$2,"o","-")) -> - | R11: =IF($F11>=R$2,"-",IF(IFERROR(VLOOKUP($G11,$U:$U,1,1),0)>=R$2,"o","-")) -> - | S11: =IF(L11="o",50000,0)+IF(M11="o",100000,0)+IF(N11="o",200000,0)+IF(O11="o",400000,0)+IF(P11="o",600000,0)+IF(Q11="o",1000000,0)+IF(R11="o",2000000,0) -> 300000
B12: 7 | C12: 박현정 | D12: 01090372486 | E12: 40737748 | F12: =IFERROR(VLOOKUP(D12,'1월'!D:F,3,0),) -> 2 | G12: 6 | L12: =IF($F12>=L$2,"-",IF(IFERROR(VLOOKUP($G12,$U:$U,1,1),0)>=L$2,"o","-")) -> - | M12: =IF($F12>=M$2,"-",IF(IFERROR(VLOOKUP($G12,$U:$U,1,1),0)>=M$2,"o","-")) -> o | N12: =IF($F12>=N$2,"-",IF(IFERROR(VLOOKUP($G12,$U:$U,1,1),0)>=N$2,"o","-")) -> o | O12: =IF($F12>=O$2,"-",IF(IFERROR(VLOOKUP($G12,$U:$U,1,1),0)>=O$2,"o","-")) -> - | P12: =IF($F12>=P$2,"-",IF(IFERROR(VLOOKUP($G12,$U:$U,1,1),0)>=P$2,"o","-")) -> - | Q12: =IF($F12>=Q$2,"-",IF(IFERROR(VLOOKUP($G12,$U:$U,1,1),0)>=Q$2,"o","-")) -> - | R12: =IF($F12>=R$2,"-",IF(IFERROR(VLOOKUP($G12,$U:$U,1,1),0)>=R$2,"o","-")) -> - | S12: =IF(L12="o",50000,0)+IF(M12="o",100000,0)+IF(N12="o",200000,0)+IF(O12="o",400000,0)+IF(P12="o",600000,0)+IF(Q12="o",1000000,0)+IF(R12="o",2000000,0) -> 300000
B13: 8 | C13: 이수민 | D13: 01031337315 | E13: 41507166 | F13: =IFERROR(VLOOKUP(D13,'1월'!D:F,3,0),) -> 2 | G13: 6 | L13: =IF($F13>=L$2,"-",IF(IFERROR(VLOOKUP($G13,$U:$U,1,1),0)>=L$2,"o","-")) -> - | M13: =IF($F13>=M$2,"-",IF(IFERROR(VLOOKUP($G13,$U:$U,1,1),0)>=M$2,"o","-")) -> o | N13: =IF($F13>=N$2,"-",IF(IFERROR(VLOOKUP($G13,$U:$U,1,1),0)>=N$2,"o","-")) -> o | O13: =IF($F13>=O$2,"-",IF(IFERROR(VLOOKUP($G13,$U:$U,1,1),0)>=O$2,"o","-")) -> - | P13: =IF($F13>=P$2,"-",IF(IFERROR(VLOOKUP($G13,$U:$U,1,1),0)>=P$2,"o","-")) -> - | Q13: =IF($F13>=Q$2,"-",IF(IFERROR(VLOOKUP($G13,$U:$U,1,1),0)>=Q$2,"o","-")) -> - | R13: =IF($F13>=R$2,"-",IF(IFERROR(VLOOKUP($G13,$U:$U,1,1),0)>=R$2,"o","-")) -> - | S13: =IF(L13="o",50000,0)+IF(M13="o",100000,0)+IF(N13="o",200000,0)+IF(O13="o",400000,0)+IF(P13="o",600000,0)+IF(Q13="o",1000000,0)+IF(R13="o",2000000,0) -> 300000
B14: 9 | C14: 김미연 | D14: 01099370290 | E14: 41900231 | F14: =IFERROR(VLOOKUP(D14,'1월'!D:F,3,0),) -> 2 | G14: 6 | L14: =IF($F14>=L$2,"-",IF(IFERROR(VLOOKUP($G14,$U:$U,1,1),0)>=L$2,"o","-")) -> - | M14: =IF($F14>=M$2,"-",IF(IFERROR(VLOOKUP($G14,$U:$U,1,1),0)>=M$2,"o","-")) -> o | N14: =IF($F14>=N$2,"-",IF(IFERROR(VLOOKUP($G14,$U:$U,1,1),0)>=N$2,"o","-")) -> o | O14: =IF($F14>=O$2,"-",IF(IFERROR(VLOOKUP($G14,$U:$U,1,1),0)>=O$2,"o","-")) -> - | P14: =IF($F14>=P$2,"-",IF(IFERROR(VLOOKUP($G14,$U:$U,1,1),0)>=P$2,"o","-")) -> - | Q14: =IF($F14>=Q$2,"-",IF(IFERROR(VLOOKUP($G14,$U:$U,1,1),0)>=Q$2,"o","-")) -> - | R14: =IF($F14>=R$2,"-",IF(IFERROR(VLOOKUP($G14,$U:$U,1,1),0)>=R$2,"o","-")) -> - | S14: =IF(L14="o",50000,0)+IF(M14="o",100000,0)+IF(N14="o",200000,0)+IF(O14="o",400000,0)+IF(P14="o",600000,0)+IF(Q14="o",1000000,0)+IF(R14="o",2000000,0) -> 300000
B15: 10 | C15: 이소희 | D15: 01027338936 | E15: 41601954 | F15: =IFERROR(VLOOKUP(D15,'1월'!D:F,3,0),) -> 4 | G15: 6 | L15: =IF($F15>=L$2,"-",IF(IFERROR(VLOOKUP($G15,$U:$U,1,1),0)>=L$2,"o","-")) -> - | M15: =IF($F15>=M$2,"-",IF(IFERROR(VLOOKUP($G15,$U:$U,1,1),0)>=M$2,"o","-")) -> - | N15: =IF($F15>=N$2,"-",IF(IFERROR(VLOOKUP($G15,$U:$U,1,1),0)>=N$2,"o","-")) -> o | O15: =IF($F15>=O$2,"-",IF(IFERROR(VLOOKUP($G15,$U:$U,1,1),0)>=O$2,"o","-")) -> - | P15: =IF($F15>=P$2,"-",IF(IFERROR(VLOOKUP($G15,$U:$U,1,1),0)>=P$2,"o","-")) -> - | Q15: =IF($F15>=Q$2,"-",IF(IFERROR(VLOOKUP($G15,$U:$U,1,1),0)>=Q$2,"o","-")) -> - | R15: =IF($F15>=R$2,"-",IF(IFERROR(VLOOKUP($G15,$U:$U,1,1),0)>=R$2,"o","-")) -> - | S15: =IF(L15="o",50000,0)+IF(M15="o",100000,0)+IF(N15="o",200000,0)+IF(O15="o",400000,0)+IF(P15="o",600000,0)+IF(Q15="o",1000000,0)+IF(R15="o",2000000,0) -> 200000
B16: 11 | C16: 류민지 | D16: 01066844589 | E16: 41605446 | F16: =IFERROR(VLOOKUP(D16,'1월'!D:F,3,0),) -> 4 | G16: 6 | L16: =IF($F16>=L$2,"-",IF(IFERROR(VLOOKUP($G16,$U:$U,1,1),0)>=L$2,"o","-")) -> - | M16: =IF($F16>=M$2,"-",IF(IFERROR(VLOOKUP($G16,$U:$U,1,1),0)>=M$2,"o","-")) -> - | N16: =IF($F16>=N$2,"-",IF(IFERROR(VLOOKUP($G16,$U:$U,1,1),0)>=N$2,"o","-")) -> o | O16: =IF($F16>=O$2,"-",IF(IFERROR(VLOOKUP($G16,$U:$U,1,1),0)>=O$2,"o","-")) -> - | P16: =IF($F16>=P$2,"-",IF(IFERROR(VLOOKUP($G16,$U:$U,1,1),0)>=P$2,"o","-")) -> - | Q16: =IF($F16>=Q$2,"-",IF(IFERROR(VLOOKUP($G16,$U:$U,1,1),0)>=Q$2,"o","-")) -> - | R16: =IF($F16>=R$2,"-",IF(IFERROR(VLOOKUP($G16,$U:$U,1,1),0)>=R$2,"o","-")) -> - | S16: =IF(L16="o",50000,0)+IF(M16="o",100000,0)+IF(N16="o",200000,0)+IF(O16="o",400000,0)+IF(P16="o",600000,0)+IF(Q16="o",1000000,0)+IF(R16="o",2000000,0) -> 200000
B17: 12 | C17: 박지원 | D17: 01087685824 | E17: 42402189 | F17: =IFERROR(VLOOKUP(D17,'1월'!D:F,3,0),) -> 4 | G17: 6 | L17: =IF($F17>=L$2,"-",IF(IFERROR(VLOOKUP($G17,$U:$U,1,1),0)>=L$2,"o","-")) -> - | M17: =IF($F17>=M$2,"-",IF(IFERROR(VLOOKUP($G17,$U:$U,1,1),0)>=M$2,"o","-")) -> - | N17: =IF($F17>=N$2,"-",IF(IFERROR(VLOOKUP($G17,$U:$U,1,1),0)>=N$2,"o","-")) -> o | O17: =IF($F17>=O$2,"-",IF(IFERROR(VLOOKUP($G17,$U:$U,1,1),0)>=O$2,"o","-")) -> - | P17: =IF($F17>=P$2,"-",IF(IFERROR(VLOOKUP($G17,$U:$U,1,1),0)>=P$2,"o","-")) -> - | Q17: =IF($F17>=Q$2,"-",IF(IFERROR(VLOOKUP($G17,$U:$U,1,1),0)>=Q$2,"o","-")) -> - | R17: =IF($F17>=R$2,"-",IF(IFERROR(VLOOKUP($G17,$U:$U,1,1),0)>=R$2,"o","-")) -> - | S17: =IF(L17="o",50000,0)+IF(M17="o",100000,0)+IF(N17="o",200000,0)+IF(O17="o",400000,0)+IF(P17="o",600000,0)+IF(Q17="o",1000000,0)+IF(R17="o",2000000,0) -> 200000
B18: 13 | C18: 강현욱 | D18: 01052849590 | E18: 31200112 | F18: =IFERROR(VLOOKUP(D18,'1월'!D:F,3,0),) -> 0 | G18: 4 | L18: =IF($F18>=L$2,"-",IF(IFERROR(VLOOKUP($G18,$U:$U,1,1),0)>=L$2,"o","-")) -> o | M18: =IF($F18>=M$2,"-",IF(IFERROR(VLOOKUP($G18,$U:$U,1,1),0)>=M$2,"o","-")) -> o | N18: =IF($F18>=N$2,"-",IF(IFERROR(VLOOKUP($G18,$U:$U,1,1),0)>=N$2,"o","-")) -> - | O18: =IF($F18>=O$2,"-",IF(IFERROR(VLOOKUP($G18,$U:$U,1,1),0)>=O$2,"o","-")) -> - | P18: =IF($F18>=P$2,"-",IF(IFERROR(VLOOKUP($G18,$U:$U,1,1),0)>=P$2,"o","-")) -> - | Q18: =IF($F18>=Q$2,"-",IF(IFERROR(VLOOKUP($G18,$U:$U,1,1),0)>=Q$2,"o","-")) -> - | R18: =IF($F18>=R$2,"-",IF(IFERROR(VLOOKUP($G18,$U:$U,1,1),0)>=R$2,"o","-")) -> - | S18: =IF(L18="o",50000,0)+IF(M18="o",100000,0)+IF(N18="o",200000,0)+IF(O18="o",400000,0)+IF(P18="o",600000,0)+IF(Q18="o",1000000,0)+IF(R18="o",2000000,0) -> 150000
B19: 14 | C19: 윤지연 | D19: 01029693439 | E19: 41304873 | F19: =IFERROR(VLOOKUP(D19,'1월'!D:F,3,0),) -> 0 | G19: 4 | L19: =IF($F19>=L$2,"-",IF(IFERROR(VLOOKUP($G19,$U:$U,1,1),0)>=L$2,"o","-")) -> o | M19: =IF($F19>=M$2,"-",IF(IFERROR(VLOOKUP($G19,$U:$U,1,1),0)>=M$2,"o","-")) -> o | N19: =IF($F19>=N$2,"-",IF(IFERROR(VLOOKUP($G19,$U:$U,1,1),0)>=N$2,"o","-")) -> - | O19: =IF($F19>=O$2,"-",IF(IFERROR(VLOOKUP($G19,$U:$U,1,1),0)>=O$2,"o","-")) -> - | P19: =IF($F19>=P$2,"-",IF(IFERROR(VLOOKUP($G19,$U:$U,1,1),0)>=P$2,"o","-")) -> - | Q19: =IF($F19>=Q$2,"-",IF(IFERROR(VLOOKUP($G19,$U:$U,1,1),0)>=Q$2,"o","-")) -> - | R19: =IF($F19>=R$2,"-",IF(IFERROR(VLOOKUP($G19,$U:$U,1,1),0)>=R$2,"o","-")) -> - | S19: =IF(L19="o",50000,0)+IF(M19="o",100000,0)+IF(N19="o",200000,0)+IF(O19="o",400000,0)+IF(P19="o",600000,0)+IF(Q19="o",1000000,0)+IF(R19="o",2000000,0) -> 150000 | U19: [우리카드]
B20: 15 | C20: 송우근 | D20: 01095088590 | E20: 31700414 | F20: =IFERROR(VLOOKUP(D20,'1월'!D:F,3,0),) -> 0 | G20: 4 | L20: =IF($F20>=L$2,"-",IF(IFERROR(VLOOKUP($G20,$U:$U,1,1),0)>=L$2,"o","-")) -> o | M20: =IF($F20>=M$2,"-",IF(IFERROR(VLOOKUP($G20,$U:$U,1,1),0)>=M$2,"o","-")) -> o | N20: =IF($F20>=N$2,"-",IF(IFERROR(VLOOKUP($G20,$U:$U,1,1),0)>=N$2,"o","-")) -> - | O20: =IF($F20>=O$2,"-",IF(IFERROR(VLOOKUP($G20,$U:$U,1,1),0)>=O$2,"o","-")) -> - | P20: =IF($F20>=P$2,"-",IF(IFERROR(VLOOKUP($G20,$U:$U,1,1),0)>=P$2,"o","-")) -> - | Q20: =IF($F20>=Q$2,"-",IF(IFERROR(VLOOKUP($G20,$U:$U,1,1),0)>=Q$2,"o","-")) -> - | R20: =IF($F20>=R$2,"-",IF(IFERROR(VLOOKUP($G20,$U:$U,1,1),0)>=R$2,"o","-")) -> - | S20: =IF(L20="o",50000,0)+IF(M20="o",100000,0)+IF(N20="o",200000,0)+IF(O20="o",400000,0)+IF(P20="o",600000,0)+IF(Q20="o",1000000,0)+IF(R20="o",2000000,0) -> 150000 | U20: 법인사업자 기업카드 모집에 힘써주셔서 감사합니다.
B21: 16 | C21: 장우영 | D21: 01095656787 | E21: 32503368 | F21: =IFERROR(VLOOKUP(D21,'1월'!D:F,3,0),) -> 0 | G21: 4 | L21: =IF($F21>=L$2,"-",IF(IFERROR(VLOOKUP($G21,$U:$U,1,1),0)>=L$2,"o","-")) -> o | M21: =IF($F21>=M$2,"-",IF(IFERROR(VLOOKUP($G21,$U:$U,1,1),0)>=M$2,"o","-")) -> o | N21: =IF($F21>=N$2,"-",IF(IFERROR(VLOOKUP($G21,$U:$U,1,1),0)>=N$2,"o","-")) -> - | O21: =IF($F21>=O$2,"-",IF(IFERROR(VLOOKUP($G21,$U:$U,1,1),0)>=O$2,"o","-")) -> - | P21: =IF($F21>=P$2,"-",IF(IFERROR(VLOOKUP($G21,$U:$U,1,1),0)>=P$2,"o","-")) -> - | Q21: =IF($F21>=Q$2,"-",IF(IFERROR(VLOOKUP($G21,$U:$U,1,1),0)>=Q$2,"o","-")) -> - | R21: =IF($F21>=R$2,"-",IF(IFERROR(VLOOKUP($G21,$U:$U,1,1),0)>=R$2,"o","-")) -> - | S21: =IF(L21="o",50000,0)+IF(M21="o",100000,0)+IF(N21="o",200000,0)+IF(O21="o",400000,0)+IF(P21="o",600000,0)+IF(Q21="o",1000000,0)+IF(R21="o",2000000,0) -> 150000 | U21: 첨부된 url 통해 원하시는 상품 골라주세요!
B22: 17 | C22: 김형열 | D22: 01029351126 | E22: 31500498 | F22: =IFERROR(VLOOKUP(D22,'1월'!D:F,3,0),) -> 0 | G22: 4 | L22: =IF($F22>=L$2,"-",IF(IFERROR(VLOOKUP($G22,$U:$U,1,1),0)>=L$2,"o","-")) -> o | M22: =IF($F22>=M$2,"-",IF(IFERROR(VLOOKUP($G22,$U:$U,1,1),0)>=M$2,"o","-")) -> o | N22: =IF($F22>=N$2,"-",IF(IFERROR(VLOOKUP($G22,$U:$U,1,1),0)>=N$2,"o","-")) -> - | O22: =IF($F22>=O$2,"-",IF(IFERROR(VLOOKUP($G22,$U:$U,1,1),0)>=O$2,"o","-")) -> - | P22: =IF($F22>=P$2,"-",IF(IFERROR(VLOOKUP($G22,$U:$U,1,1),0)>=P$2,"o","-")) -> - | Q22: =IF($F22>=Q$2,"-",IF(IFERROR(VLOOKUP($G22,$U:$U,1,1),0)>=Q$2,"o","-")) -> - | R22: =IF($F22>=R$2,"-",IF(IFERROR(VLOOKUP($G22,$U:$U,1,1),0)>=R$2,"o","-")) -> - | S22: =IF(L22="o",50000,0)+IF(M22="o",100000,0)+IF(N22="o",200000,0)+IF(O22="o",400000,0)+IF(P22="o",600000,0)+IF(Q22="o",1000000,0)+IF(R22="o",2000000,0) -> 150000
B23: 18 | C23: 문수희 | D23: 01087897534 | E23: 41300282 | F23: =IFERROR(VLOOKUP(D23,'1월'!D:F,3,0),) -> 0 | G23: 4 | L23: =IF($F23>=L$2,"-",IF(IFERROR(VLOOKUP($G23,$U:$U,1,1),0)>=L$2,"o","-")) -> o | M23: =IF($F23>=M$2,"-",IF(IFERROR(VLOOKUP($G23,$U:$U,1,1),0)>=M$2,"o","-")) -> o | N23: =IF($F23>=N$2,"-",IF(IFERROR(VLOOKUP($G23,$U:$U,1,1),0)>=N$2,"o","-")) -> - | O23: =IF($F23>=O$2,"-",IF(IFERROR(VLOOKUP($G23,$U:$U,1,1),0)>=O$2,"o","-")) -> - | P23: =IF($F23>=P$2,"-",IF(IFERROR(VLOOKUP($G23,$U:$U,1,1),0)>=P$2,"o","-")) -> - | Q23: =IF($F23>=Q$2,"-",IF(IFERROR(VLOOKUP($G23,$U:$U,1,1),0)>=Q$2,"o","-")) -> - | R23: =IF($F23>=R$2,"-",IF(IFERROR(VLOOKUP($G23,$U:$U,1,1),0)>=R$2,"o","-")) -> - | S23: =IF(L23="o",50000,0)+IF(M23="o",100000,0)+IF(N23="o",200000,0)+IF(O23="o",400000,0)+IF(P23="o",600000,0)+IF(Q23="o",1000000,0)+IF(R23="o",2000000,0) -> 150000 | U23: 한번이 아니라 더더더 좋은걸로 계속드립니다!!
B24: 19 | C24: 김성현 | D24: 01098340814 | E24: 31300247 | F24: =IFERROR(VLOOKUP(D24,'1월'!D:F,3,0),) -> 0 | G24: 4 | L24: =IF($F24>=L$2,"-",IF(IFERROR(VLOOKUP($G24,$U:$U,1,1),0)>=L$2,"o","-")) -> o | M24: =IF($F24>=M$2,"-",IF(IFERROR(VLOOKUP($G24,$U:$U,1,1),0)>=M$2,"o","-")) -> o | N24: =IF($F24>=N$2,"-",IF(IFERROR(VLOOKUP($G24,$U:$U,1,1),0)>=N$2,"o","-")) -> - | O24: =IF($F24>=O$2,"-",IF(IFERROR(VLOOKUP($G24,$U:$U,1,1),0)>=O$2,"o","-")) -> - | P24: =IF($F24>=P$2,"-",IF(IFERROR(VLOOKUP($G24,$U:$U,1,1),0)>=P$2,"o","-")) -> - | Q24: =IF($F24>=Q$2,"-",IF(IFERROR(VLOOKUP($G24,$U:$U,1,1),0)>=Q$2,"o","-")) -> - | R24: =IF($F24>=R$2,"-",IF(IFERROR(VLOOKUP($G24,$U:$U,1,1),0)>=R$2,"o","-")) -> - | S24: =IF(L24="o",50000,0)+IF(M24="o",100000,0)+IF(N24="o",200000,0)+IF(O24="o",400000,0)+IF(P24="o",600000,0)+IF(Q24="o",1000000,0)+IF(R24="o",2000000,0) -> 150000 | U24: 법인 신규모집 구간 달성할 때마다 포상 받아가세요! (이미지 참고)
B25: 20 | C25: 박진우 | D25: 01092226750 | E25: 31300670 | F25: =IFERROR(VLOOKUP(D25,'1월'!D:F,3,0),) -> 0 | G25: 4 | L25: =IF($F25>=L$2,"-",IF(IFERROR(VLOOKUP($G25,$U:$U,1,1),0)>=L$2,"o","-")) -> o | M25: =IF($F25>=M$2,"-",IF(IFERROR(VLOOKUP($G25,$U:$U,1,1),0)>=M$2,"o","-")) -> o | N25: =IF($F25>=N$2,"-",IF(IFERROR(VLOOKUP($G25,$U:$U,1,1),0)>=N$2,"o","-")) -> - | O25: =IF($F25>=O$2,"-",IF(IFERROR(VLOOKUP($G25,$U:$U,1,1),0)>=O$2,"o","-")) -> - | P25: =IF($F25>=P$2,"-",IF(IFERROR(VLOOKUP($G25,$U:$U,1,1),0)>=P$2,"o","-")) -> - | Q25: =IF($F25>=Q$2,"-",IF(IFERROR(VLOOKUP($G25,$U:$U,1,1),0)>=Q$2,"o","-")) -> - | R25: =IF($F25>=R$2,"-",IF(IFERROR(VLOOKUP($G25,$U:$U,1,1),0)>=R$2,"o","-")) -> - | S25: =IF(L25="o",50000,0)+IF(M25="o",100000,0)+IF(N25="o",200000,0)+IF(O25="o",400000,0)+IF(P25="o",600000,0)+IF(Q25="o",1000000,0)+IF(R25="o",2000000,0) -> 150000
B26: 21 | C26: 김건우 | D26: 01050336727 | E26: 31402992 | F26: =IFERROR(VLOOKUP(D26,'1월'!D:F,3,0),) -> 0 | G26: 4 | L26: =IF($F26>=L$2,"-",IF(IFERROR(VLOOKUP($G26,$U:$U,1,1),0)>=L$2,"o","-")) -> o | M26: =IF($F26>=M$2,"-",IF(IFERROR(VLOOKUP($G26,$U:$U,1,1),0)>=M$2,"o","-")) -> o | N26: =IF($F26>=N$2,"-",IF(IFERROR(VLOOKUP($G26,$U:$U,1,1),0)>=N$2,"o","-")) -> - | O26: =IF($F26>=O$2,"-",IF(IFERROR(VLOOKUP($G26,$U:$U,1,1),0)>=O$2,"o","-")) -> - | P26: =IF($F26>=P$2,"-",IF(IFERROR(VLOOKUP($G26,$U:$U,1,1),0)>=P$2,"o","-")) -> - | Q26: =IF($F26>=Q$2,"-",IF(IFERROR(VLOOKUP($G26,$U:$U,1,1),0)>=Q$2,"o","-")) -> - | R26: =IF($F26>=R$2,"-",IF(IFERROR(VLOOKUP($G26,$U:$U,1,1),0)>=R$2,"o","-")) -> - | S26: =IF(L26="o",50000,0)+IF(M26="o",100000,0)+IF(N26="o",200000,0)+IF(O26="o",400000,0)+IF(P26="o",600000,0)+IF(Q26="o",1000000,0)+IF(R26="o",2000000,0) -> 150000
B27: 22 | C27: 이진동 | D27: 01099995429 | E27: 32001095 | F27: =IFERROR(VLOOKUP(D27,'1월'!D:F,3,0),) -> 0 | G27: 4 | L27: =IF($F27>=L$2,"-",IF(IFERROR(VLOOKUP($G27,$U:$U,1,1),0)>=L$2,"o","-")) -> o | M27: =IF($F27>=M$2,"-",IF(IFERROR(VLOOKUP($G27,$U:$U,1,1),0)>=M$2,"o","-")) -> o | N27: =IF($F27>=N$2,"-",IF(IFERROR(VLOOKUP($G27,$U:$U,1,1),0)>=N$2,"o","-")) -> - | O27: =IF($F27>=O$2,"-",IF(IFERROR(VLOOKUP($G27,$U:$U,1,1),0)>=O$2,"o","-")) -> - | P27: =IF($F27>=P$2,"-",IF(IFERROR(VLOOKUP($G27,$U:$U,1,1),0)>=P$2,"o","-")) -> - | Q27: =IF($F27>=Q$2,"-",IF(IFERROR(VLOOKUP($G27,$U:$U,1,1),0)>=Q$2,"o","-")) -> - | R27: =IF($F27>=R$2,"-",IF(IFERROR(VLOOKUP($G27,$U:$U,1,1),0)>=R$2,"o","-")) -> - | S27: =IF(L27="o",50000,0)+IF(M27="o",100000,0)+IF(N27="o",200000,0)+IF(O27="o",400000,0)+IF(P27="o",600000,0)+IF(Q27="o",1000000,0)+IF(R27="o",2000000,0) -> 150000
B28: 23 | C28: 박진수 | D28: 01026304125 | E28: 31801142 | F28: =IFERROR(VLOOKUP(D28,'1월'!D:F,3,0),) -> 0 | G28: 4 | L28: =IF($F28>=L$2,"-",IF(IFERROR(VLOOKUP($G28,$U:$U,1,1),0)>=L$2,"o","-")) -> o | M28: =IF($F28>=M$2,"-",IF(IFERROR(VLOOKUP($G28,$U:$U,1,1),0)>=M$2,"o","-")) -> o | N28: =IF($F28>=N$2,"-",IF(IFERROR(VLOOKUP($G28,$U:$U,1,1),0)>=N$2,"o","-")) -> - | O28: =IF($F28>=O$2,"-",IF(IFERROR(VLOOKUP($G28,$U:$U,1,1),0)>=O$2,"o","-")) -> - | P28: =IF($F28>=P$2,"-",IF(IFERROR(VLOOKUP($G28,$U:$U,1,1),0)>=P$2,"o","-")) -> - | Q28: =IF($F28>=Q$2,"-",IF(IFERROR(VLOOKUP($G28,$U:$U,1,1),0)>=Q$2,"o","-")) -> - | R28: =IF($F28>=R$2,"-",IF(IFERROR(VLOOKUP($G28,$U:$U,1,1),0)>=R$2,"o","-")) -> - | S28: =IF(L28="o",50000,0)+IF(M28="o",100000,0)+IF(N28="o",200000,0)+IF(O28="o",400000,0)+IF(P28="o",600000,0)+IF(Q28="o",1000000,0)+IF(R28="o",2000000,0) -> 150000
B29: 24 | C29: 신동훈 | D29: 01085437136 | E29: 31500830 | F29: =IFERROR(VLOOKUP(D29,'1월'!D:F,3,0),) -> 0 | G29: 4 | L29: =IF($F29>=L$2,"-",IF(IFERROR(VLOOKUP($G29,$U:$U,1,1),0)>=L$2,"o","-")) -> o | M29: =IF($F29>=M$2,"-",IF(IFERROR(VLOOKUP($G29,$U:$U,1,1),0)>=M$2,"o","-")) -> o | N29: =IF($F29>=N$2,"-",IF(IFERROR(VLOOKUP($G29,$U:$U,1,1),0)>=N$2,"o","-")) -> - | O29: =IF($F29>=O$2,"-",IF(IFERROR(VLOOKUP($G29,$U:$U,1,1),0)>=O$2,"o","-")) -> - | P29: =IF($F29>=P$2,"-",IF(IFERROR(VLOOKUP($G29,$U:$U,1,1),0)>=P$2,"o","-")) -> - | Q29: =IF($F29>=Q$2,"-",IF(IFERROR(VLOOKUP($G29,$U:$U,1,1),0)>=Q$2,"o","-")) -> - | R29: =IF($F29>=R$2,"-",IF(IFERROR(VLOOKUP($G29,$U:$U,1,1),0)>=R$2,"o","-")) -> - | S29: =IF(L29="o",50000,0)+IF(M29="o",100000,0)+IF(N29="o",200000,0)+IF(O29="o",400000,0)+IF(P29="o",600000,0)+IF(Q29="o",1000000,0)+IF(R29="o",2000000,0) -> 150000
B30: 25 | C30: 정지은 | D30: 01052320748 | E30: 42201425 | F30: =IFERROR(VLOOKUP(D30,'1월'!D:F,3,0),) -> 0 | G30: 4 | L30: =IF($F30>=L$2,"-",IF(IFERROR(VLOOKUP($G30,$U:$U,1,1),0)>=L$2,"o","-")) -> o | M30: =IF($F30>=M$2,"-",IF(IFERROR(VLOOKUP($G30,$U:$U,1,1),0)>=M$2,"o","-")) -> o | N30: =IF($F30>=N$2,"-",IF(IFERROR(VLOOKUP($G30,$U:$U,1,1),0)>=N$2,"o","-")) -> - | O30: =IF($F30>=O$2,"-",IF(IFERROR(VLOOKUP($G30,$U:$U,1,1),0)>=O$2,"o","-")) -> - | P30: =IF($F30>=P$2,"-",IF(IFERROR(VLOOKUP($G30,$U:$U,1,1),0)>=P$2,"o","-")) -> - | Q30: =IF($F30>=Q$2,"-",IF(IFERROR(VLOOKUP($G30,$U:$U,1,1),0)>=Q$2,"o","-")) -> - | R30: =IF($F30>=R$2,"-",IF(IFERROR(VLOOKUP($G30,$U:$U,1,1),0)>=R$2,"o","-")) -> - | S30: =IF(L30="o",50000,0)+IF(M30="o",100000,0)+IF(N30="o",200000,0)+IF(O30="o",400000,0)+IF(P30="o",600000,0)+IF(Q30="o",1000000,0)+IF(R30="o",2000000,0) -> 150000
B31: 26 | C31: 최휘 | D31: 01068588523 | E31: 31700838 | F31: =IFERROR(VLOOKUP(D31,'1월'!D:F,3,0),) -> 0 | G31: 4 | L31: =IF($F31>=L$2,"-",IF(IFERROR(VLOOKUP($G31,$U:$U,1,1),0)>=L$2,"o","-")) -> o | M31: =IF($F31>=M$2,"-",IF(IFERROR(VLOOKUP($G31,$U:$U,1,1),0)>=M$2,"o","-")) -> o | N31: =IF($F31>=N$2,"-",IF(IFERROR(VLOOKUP($G31,$U:$U,1,1),0)>=N$2,"o","-")) -> - | O31: =IF($F31>=O$2,"-",IF(IFERROR(VLOOKUP($G31,$U:$U,1,1),0)>=O$2,"o","-")) -> - | P31: =IF($F31>=P$2,"-",IF(IFERROR(VLOOKUP($G31,$U:$U,1,1),0)>=P$2,"o","-")) -> - | Q31: =IF($F31>=Q$2,"-",IF(IFERROR(VLOOKUP($G31,$U:$U,1,1),0)>=Q$2,"o","-")) -> - | R31: =IF($F31>=R$2,"-",IF(IFERROR(VLOOKUP($G31,$U:$U,1,1),0)>=R$2,"o","-")) -> - | S31: =IF(L31="o",50000,0)+IF(M31="o",100000,0)+IF(N31="o",200000,0)+IF(O31="o",400000,0)+IF(P31="o",600000,0)+IF(Q31="o",1000000,0)+IF(R31="o",2000000,0) -> 150000
B32: 27 | C32: 김지애 | D32: 01027673400 | E32: 41301010 | F32: =IFERROR(VLOOKUP(D32,'1월'!D:F,3,0),) -> 0 | G32: 4 | L32: =IF($F32>=L$2,"-",IF(IFERROR(VLOOKUP($G32,$U:$U,1,1),0)>=L$2,"o","-")) -> o | M32: =IF($F32>=M$2,"-",IF(IFERROR(VLOOKUP($G32,$U:$U,1,1),0)>=M$2,"o","-")) -> o | N32: =IF($F32>=N$2,"-",IF(IFERROR(VLOOKUP($G32,$U:$U,1,1),0)>=N$2,"o","-")) -> - | O32: =IF($F32>=O$2,"-",IF(IFERROR(VLOOKUP($G32,$U:$U,1,1),0)>=O$2,"o","-")) -> - | P32: =IF($F32>=P$2,"-",IF(IFERROR(VLOOKUP($G32,$U:$U,1,1),0)>=P$2,"o","-")) -> - | Q32: =IF($F32>=Q$2,"-",IF(IFERROR(VLOOKUP($G32,$U:$U,1,1),0)>=Q$2,"o","-")) -> - | R32: =IF($F32>=R$2,"-",IF(IFERROR(VLOOKUP($G32,$U:$U,1,1),0)>=R$2,"o","-")) -> - | S32: =IF(L32="o",50000,0)+IF(M32="o",100000,0)+IF(N32="o",200000,0)+IF(O32="o",400000,0)+IF(P32="o",600000,0)+IF(Q32="o",1000000,0)+IF(R32="o",2000000,0) -> 150000
B33: 28 | C33: 이혜진 | D33: 01086365787 | E33: 41009259 | F33: =IFERROR(VLOOKUP(D33,'1월'!D:F,3,0),) -> 0 | G33: 4 | L33: =IF($F33>=L$2,"-",IF(IFERROR(VLOOKUP($G33,$U:$U,1,1),0)>=L$2,"o","-")) -> o | M33: =IF($F33>=M$2,"-",IF(IFERROR(VLOOKUP($G33,$U:$U,1,1),0)>=M$2,"o","-")) -> o | N33: =IF($F33>=N$2,"-",IF(IFERROR(VLOOKUP($G33,$U:$U,1,1),0)>=N$2,"o","-")) -> - | O33: =IF($F33>=O$2,"-",IF(IFERROR(VLOOKUP($G33,$U:$U,1,1),0)>=O$2,"o","-")) -> - | P33: =IF($F33>=P$2,"-",IF(IFERROR(VLOOKUP($G33,$U:$U,1,1),0)>=P$2,"o","-")) -> - | Q33: =IF($F33>=Q$2,"-",IF(IFERROR(VLOOKUP($G33,$U:$U,1,1),0)>=Q$2,"o","-")) -> - | R33: =IF($F33>=R$2,"-",IF(IFERROR(VLOOKUP($G33,$U:$U,1,1),0)>=R$2,"o","-")) -> - | S33: =IF(L33="o",50000,0)+IF(M33="o",100000,0)+IF(N33="o",200000,0)+IF(O33="o",400000,0)+IF(P33="o",600000,0)+IF(Q33="o",1000000,0)+IF(R33="o",2000000,0) -> 150000
B34: 29 | C34: 이대호 | D34: 01036867495 | E34: 31403072 | F34: =IFERROR(VLOOKUP(D34,'1월'!D:F,3,0),) -> 0 | G34: 4 | L34: =IF($F34>=L$2,"-",IF(IFERROR(VLOOKUP($G34,$U:$U,1,1),0)>=L$2,"o","-")) -> o | M34: =IF($F34>=M$2,"-",IF(IFERROR(VLOOKUP($G34,$U:$U,1,1),0)>=M$2,"o","-")) -> o | N34: =IF($F34>=N$2,"-",IF(IFERROR(VLOOKUP($G34,$U:$U,1,1),0)>=N$2,"o","-")) -> - | O34: =IF($F34>=O$2,"-",IF(IFERROR(VLOOKUP($G34,$U:$U,1,1),0)>=O$2,"o","-")) -> - | P34: =IF($F34>=P$2,"-",IF(IFERROR(VLOOKUP($G34,$U:$U,1,1),0)>=P$2,"o","-")) -> - | Q34: =IF($F34>=Q$2,"-",IF(IFERROR(VLOOKUP($G34,$U:$U,1,1),0)>=Q$2,"o","-")) -> - | R34: =IF($F34>=R$2,"-",IF(IFERROR(VLOOKUP($G34,$U:$U,1,1),0)>=R$2,"o","-")) -> - | S34: =IF(L34="o",50000,0)+IF(M34="o",100000,0)+IF(N34="o",200000,0)+IF(O34="o",400000,0)+IF(P34="o",600000,0)+IF(Q34="o",1000000,0)+IF(R34="o",2000000,0) -> 150000
B35: 30 | C35: 김건우 | D35: 01041027373 | E35: 31800107 | F35: =IFERROR(VLOOKUP(D35,'1월'!D:F,3,0),) -> 0 | G35: 4 | L35: =IF($F35>=L$2,"-",IF(IFERROR(VLOOKUP($G35,$U:$U,1,1),0)>=L$2,"o","-")) -> o | M35: =IF($F35>=M$2,"-",IF(IFERROR(VLOOKUP($G35,$U:$U,1,1),0)>=M$2,"o","-")) -> o | N35: =IF($F35>=N$2,"-",IF(IFERROR(VLOOKUP($G35,$U:$U,1,1),0)>=N$2,"o","-")) -> - | O35: =IF($F35>=O$2,"-",IF(IFERROR(VLOOKUP($G35,$U:$U,1,1),0)>=O$2,"o","-")) -> - | P35: =IF($F35>=P$2,"-",IF(IFERROR(VLOOKUP($G35,$U:$U,1,1),0)>=P$2,"o","-")) -> - | Q35: =IF($F35>=Q$2,"-",IF(IFERROR(VLOOKUP($G35,$U:$U,1,1),0)>=Q$2,"o","-")) -> - | R35: =IF($F35>=R$2,"-",IF(IFERROR(VLOOKUP($G35,$U:$U,1,1),0)>=R$2,"o","-")) -> - | S35: =IF(L35="o",50000,0)+IF(M35="o",100000,0)+IF(N35="o",200000,0)+IF(O35="o",400000,0)+IF(P35="o",600000,0)+IF(Q35="o",1000000,0)+IF(R35="o",2000000,0) -> 150000
B36: 31 | C36: 구승연 | D36: 01087624317 | E36: 42302045 | F36: =IFERROR(VLOOKUP(D36,'1월'!D:F,3,0),) -> 0 | G36: 4 | L36: =IF($F36>=L$2,"-",IF(IFERROR(VLOOKUP($G36,$U:$U,1,1),0)>=L$2,"o","-")) -> o | M36: =IF($F36>=M$2,"-",IF(IFERROR(VLOOKUP($G36,$U:$U,1,1),0)>=M$2,"o","-")) -> o | N36: =IF($F36>=N$2,"-",IF(IFERROR(VLOOKUP($G36,$U:$U,1,1),0)>=N$2,"o","-")) -> - | O36: =IF($F36>=O$2,"-",IF(IFERROR(VLOOKUP($G36,$U:$U,1,1),0)>=O$2,"o","-")) -> - | P36: =IF($F36>=P$2,"-",IF(IFERROR(VLOOKUP($G36,$U:$U,1,1),0)>=P$2,"o","-")) -> - | Q36: =IF($F36>=Q$2,"-",IF(IFERROR(VLOOKUP($G36,$U:$U,1,1),0)>=Q$2,"o","-")) -> - | R36: =IF($F36>=R$2,"-",IF(IFERROR(VLOOKUP($G36,$U:$U,1,1),0)>=R$2,"o","-")) -> - | S36: =IF(L36="o",50000,0)+IF(M36="o",100000,0)+IF(N36="o",200000,0)+IF(O36="o",400000,0)+IF(P36="o",600000,0)+IF(Q36="o",1000000,0)+IF(R36="o",2000000,0) -> 150000
... B313: 308 | C313: 견병훈 | D313: 01063534337 | E313: 31902528 | F313: =IFERROR(VLOOKUP(D313,'1월'!D:F,3,0),) -> 0 | G313: 2 | L313: =IF($F313>=L$2,"-",IF(IFERROR(VLOOKUP($G313,$U:$U,1,1),0)>=L$2,"o","-")) -> o | M313: =IF($F313>=M$2,"-",IF(IFERROR(VLOOKUP($G313,$U:$U,1,1),0)>=M$2,"o","-")) -> - | N313: =IF($F313>=N$2,"-",IF(IFERROR(VLOOKUP($G313,$U:$U,1,1),0)>=N$2,"o","-")) -> - | O313: =IF($F313>=O$2,"-",IF(IFERROR(VLOOKUP($G313,$U:$U,1,1),0)>=O$2,"o","-")) -> - | P313: =IF($F313>=P$2,"-",IF(IFERROR(VLOOKUP($G313,$U:$U,1,1),0)>=P$2,"o","-")) -> - | Q313: =IF($F313>=Q$2,"-",IF(IFERROR(VLOOKUP($G313,$U:$U,1,1),0)>=Q$2,"o","-")) -> - | R313: =IF($F313>=R$2,"-",IF(IFERROR(VLOOKUP($G313,$U:$U,1,1),0)>=R$2,"o","-")) -> - | S313: =IF(L313="o",50000,0)+IF(M313="o",100000,0)+IF(N313="o",200000,0)+IF(O313="o",400000,0)+IF(P313="o",600000,0)+IF(Q313="o",1000000,0)+IF(R313="o",2000000,0) -> 50000

Sheet 상품목록
B2: 우리카드 기업영업기획팀 상품 제안
B3: ■ 구간달성 포상 (상반기 기준)
B4: 달성구간(社) | C4: No. | D4: 상품 | E4: 가격대 | F4: 대상 예정 | G4: 할인율 | H4: 할인후 가격
B5: 2 | C5: 1 | D5: 스타벅스 e-기프트카드 5만원권 | E5: 5만원 상당 | F5: 1300
C6: 2 | D6: 루메나 듀얼 무선 미니가습기 H3 X
C7: 3 | D7: 오아 클린이스윙 전동칫솔
C8: 4 | D8: 벨킨 5000mAh 맥세이프보조배터리
C9: 5 | D9: 로지텍 무선 텐키리스 키보드 K380S
C10: 6 | D10: 로지텍 시그니처 M650 무선 마우스
C11: 7 | D11: 알로코리아 덴픽 구강세정기
B12: 4 | C12: 1 | D12: 쿠팡캐시 10만원권 | E12: 10만원 상당 | F12: 600
C13: 2 | D13: 신세계 이마트 상품권 10만원권
C14: 3 | D14: 쿠첸 전자식 에어프라이어 5L
C15: 4 | D15: 풀리오 목 어깨 마사지기 V2
C16: 5 | D16: 네스카페 돌체구스토 지니오S 터치
C17: 6 | D17: 일리 Y3.3 캡슐커피머신
C18: 7 | D18: 브리츠 BZ-MQ3 레트로 엔틱 블루투스 스피커
B19: 6 | C19: 1 | D19: 신세계 이마트 상품권 20만원 | E19: 20만원 상당 | F19: 250
C20: 2 | D20: 로지텍 MX Master 4 무선마우스
C21: 3 | D21: 에어팟 4 블루투스 이어폰 유선충전
C22: 4 | D22: 네스프레소 버츄오 플러스 캡슐커피머신
C23: 5 | D23: 스메그 미니 전기포트
C24: 6 | D24: 닌자 프로페셔널 블렌더 2.0 BR201KR
C25: 7 | D25: 풀리오 목 어깨 마사지기 V3
B26: 8 | C26: 1 | D26: 신세계 이마트 상품권 40만원 | E26: 40만원 상당 | F26: 100
C27: 2 | D27: 우마왕 최상급 한우 선물 세트 1++ No9 2kg
C28: 3 | D28: 르라보 향수 100ml (향 선택)
C29: 4 | D29: LG전자 코드제로 A5 AS520WA
C30: 5 | D30: 에어팟 프로 3
C31: 6 | D31: 삼성전자 갤럭시 워치8 블루투스 40mm
C32: 7 | D32: 미닉스 음식물 처리기 더플렌더 Basic
B33: 10 | C33: 1 | D33: 네이버페이 포인트 60만원 | E33: 60만원 상당 | F33: 60
C34: 2 | D34: 삼성 비스포크 제트 VS20C954AQB
C35: 3 | D35: 애플워치 11 GPS, 42mm, 알루미늄 케이스
C36: 4 | D36: 다이슨 슈퍼소닉 뉴럴 헤어 드라이기
C37: 5 | D37: 신라호텔 디럭스룸 초대권
C38: 6 | D38: 신세계 이마트 상품권 60만원
C39: 7 | D39: 시디즈 컴퓨터 의자 T80
B40: 15 | C40: 1 | D40: 네이버페이 포인트 100만원 | E40: 100만원 상당 | F40: 10
C41: 2 | D41: 샤크 에보파워 시스템 부스트+ LC751KRLV
...
